Workbook

Sheet 交易总表
A1: 日期 | B1: 分段 | C1: 记录类型 | D1: 时间 | E1: 股票代码 | F1: 名称 | G1: 方向 | H1: 动作 | I1: 数量 | J1: 价格 | K1: 平均成本 | L1: 成交/计划金额 | M1: 佣金 | N1: 印花税 | O1: 过户/经手费 | P1: 交易成本 | Q1: 现金净流 | R1: 组合现金 | S1: 组合市值 | T1: 个股市值 | U1: 期初权益 | V1: 期末权益/总资产 | W1: 当日盈亏 | X1: 当日收益率% | Y1: 已实现盈亏 | Z1: 未实现盈亏 | AA1: 未实现收益率% | AB1: 总暴露% | AC1: 仓位% | AD1: 最大回撤% | AE1: 风险状态 | AF1: 策略标签 | AG1: 策略ID | AH1: 评分因子 | AI1: 因子/策略权重 | AJ1: 策略状态 | AK1: 买卖/复查理由 | AL1: 验证口径 | AM1: 后续验证 | AN1: 判断状态 | AO1: 备注
A2: 2026-06-05 | B2: 2026-06-05 期初持仓同步 | C2: 期初持仓 | E2: 600519 | F2: 贵州茅台 | G2: 买入 | H2: 期初持仓同步 | I2: 100 | J2: 1500.9501 | L2: 150095.01 | M2: 45.03 | N2: 0.00 | O2: 0.00 | P2: 45.03 | Q2: -150140.04 | AF2: manual-sync | AG2: manual-sync | AK2: 不是2026年2月真实交易；仅用于承接量化系统开始时已存在的600519纸面持仓 | AN2: 已成交 | AO2: 原始来源为本地回测未确认卖出后的持仓同步；总表按2026-06-05期初持仓处理，不作为量化交易启动前成交。
A3: 2026-06-05 | B3: 2026-06-05 原Excel交易计划 | C3: 交易计划 | D3: 13:00 | E3: 000001 | F3: 平安银行 | G3: 买入 | H3: 13:00若强势延续则纸面买入 | I3: 36200 | J3: 11.02 | L3: 398924 | AC3: 39.8924 | AF3: 纸面买入主仓 | AG3: 纸面买入主仓 | AK3: 维持强于池子；不跌回11.02；量能不恶化 | AL3: 方向、动作、纪律分开评估 | AM3: 需补审 | AN3: 逾期未留证 | AO3: 仍为观察池中唯一尝试转强样本，执行预设主攻仓。；状态规范化：原“待验证”，因已过复核时点且未留后验证据，改为“逾期未留证”；原后续验证=未填写具体复核时点
A4: 2026-06-05 | B4: 2026-06-05 原Excel交易计划 | C4: 交易计划 | D4: 13:00 | E4: 000858 | F4: 五粮液 | G4: 买入 | H4: 13:00只在反弹延续时纸面买入 | I4: 3000 | J4: 81.69 | L4: 245070 | AC4: 24.507 | AF4: 纸面买入副仓 | AG4: 纸面买入副仓 | AK4: 不破81.52；反弹有承接；不能冲高回落 | AL4: 方向、动作、纪律分开评估 | AM4: 需补审 | AN4: 逾期未留证 | AO4: 评分最高但仍弱势，按预设只给副攻反弹仓。；状态规范化：原“待验证”，因已过复核时点且未留后验证据，改为“逾期未留证”；原后续验证=未填写具体复核时点
A5: 2026-06-05 | B5: 2026-06-05 原Excel交易计划 | C5: 交易计划 | D5: 13:00 | E5: 600000 | F5: 浦发银行 | G5: 买入 | H5: 13:00小仓纸面验证 | I5: 16200 | J5: 9.23 | L5: 149526 | AC5: 14.9526 | AF5: 纸面买入小仓 | AG5: 纸面买入小仓 | AK5: 维持9.23上方；波动低；不弱于银行样本 | AL5: 方向、动作、纪律分开评估 | AM5: 需补审 | AN5: 逾期未留证 | AO5: 低波动稳定仓，按预设小仓验证。；状态规范化：原“待验证”，因已过复核时点且未留后验证据，改为“逾期未留证”；原后续验证=未填写具体复核时点
A6: 2026-06-05 | B6: 2026-06-05 原Excel交易计划 | C6: 交易计划 | E6: 600519 | F6: 贵州茅台 | G6: 买入 | H6: 连续持仓估值，不日结卖出 | I6: 100 | J6: 1501.4004 | L6: 150140.04 | T6: 125600 | Y6: -24540.04 | Z6: -24540.04 | AA6: -16.3448 | AC6: 15.014 | AF6: 不买/对照 | AG6: 不买/对照 | AK6: 无 | AL6: 用于检验防守判断 | AM6: 需补审 | AN6: 逾期未留证 | AO6: 保留连续持仓；不做日结卖出；今日按1256.00估值，未实现盈亏-24540.04。；状态规范化：原“待验证”，因已过复核时点且未留后验证据，改为“逾期未留证”；原后续验证=未填写具体复核时点
A7: 2026-06-05 | B7: 2026-06-05 13:00组合快照 | C7: 盘中复查 | D7: 13:00 | H7: 13:00纸面建仓完成 | AK7: 历史Excel盘中组合快照，非正式日结权益行 | AO7: 原组合快照迁出: cash=206480, stock_value=793520, daily_return_pct=0
A8: 2026-06-05 | B8: 2026-06-05 13:32组合快照 | C8: 盘中复查 | D8: 13:32 | H8: 13:30复查：不加仓，保留现金 | AK8: 历史Excel盘中组合快照，非正式日结权益行 | AO8: 浮盈亏=-682.00；原组合快照迁出: cash=206480, stock_value=999318, daily_return_pct=-0.0682
A9: 2026-06-05 | B9: 2026-06-05 建仓决策 | C9: 盘中复查 | D9: 13:00 | E9: 000001 | F9: 平安银行 | G9: 做多 | H9: 买入 | I9: 36200 | J9: 11.02 | L9: 398924 | T9: 398924 | AC9: 39.8924 | AK9: 仍为观察池中唯一尝试转强样本，执行预设主攻仓。 | AM9: 需补审 | AN9: 逾期未留证 | AO9: 状态规范化：原“待验证”，因已过复核时点且未留后验证据，改为“逾期未留证”；原后续验证=待13:15验证
A10: 2026-06-05 | B10: 2026-06-05 13:30复查 | C10: 盘中复查 | D10: 13:32 | E10: 000001 | F10: 平安银行 | G10: 做多 | H10: 持有，不加仓 | I10: 36200 | J10: 11 | L10: 398200 | R10: 206480 | S10: 604680 | T10: 398200 | AC10: 39.82 | AK10: 较13:00买入价回落，暂不触发止损，但不能加仓。 | AM10: 需补审 | AN10: 逾期未留证 | AO10: 补做13:30复查；原权益列迁出: daily_return_pct=-39.532；状态规范化：原“待验证”，因已过复核时点且未留后验证据，改为“逾期未留证”；原后续验证=待14:00验证
A11: 2026-06-05 | B11: 2026-06-05 建仓决策 | C11: 盘中复查 | D11: 13:00 | E11: 000858 | F11: 五粮液 | G11: 做多 | H11: 买入 | I11: 3000 | J11: 81.69 | L11: 245070 | T11: 245070 | AC11: 24.507 | AK11: 评分最高但仍弱势，按预设只给副攻反弹仓。 | AM11: 需补审 | AN11: 逾期未留证 | AO11: 状态规范化：原“待验证”，因已过复核时点且未留后验证据，改为“逾期未留证”；原后续验证=待13:15验证
A12: 2026-06-05 | B12: 2026-06-05 13:30复查 | C12: 盘中复查 | D12: 13:32 | E12: 000858 | F12: 五粮液 | G12: 做多 | H12: 持有，不加仓 | I12: 3000 | J12: 81.38 | L12: 244140 | R12: 206480 | S12: 848820 | T12: 244140 | AC12: 24.414 | AK12: 较13:00买入价回落，暂不触发止损，但不能加仓。 | AM12: 需补审 | AN12: 逾期未留证 | AO12: 补做13:30复查；原权益列迁出: daily_return_pct=-15.118；状态规范化：原“待验证”，因已过复核时点且未留后验证据，改为“逾期未留证”；原后续验证=待14:00验证
A13: 2026-06-05 | B13: 2026-06-05 建仓决策 | C13: 盘中复查 | D13: 13:00 | E13: 300750 | F13: 宁德时代 | G13: 不交易 | H13: 观察 | I13: 0 | J13: 408.22 | L13: 0 | T13: 0 | AC13: 0 | AK13: 13:00仅持平，未显示明显转强，条件仓不触发。 | AM13: 需补审 | AN13: 逾期未留证 | AO13: 状态规范化：原“待验证”，因已过复核时点且未留后验证据，改为“逾期未留证”；原后续验证=待13:15验证
A14: 2026-06-05 | B14: 2026-06-05 13:30复查 | C14: 盘中复查 | D14: 13:32 | E14: 300750 | F14: 宁德时代 | G14: 不交易 | H14: 继续观察 | I14: 0 | J14: 407.67 | L14: 0 | R14: 206480 | S14: 999318 | T14: 0 | AC14: 0 | AK14: 条件仓仍未触发。 | AM14: 需补审 | AN14: 逾期未留证 | AO14: 补做13:30复查；原权益列迁出: daily_return_pct=-0.0682；状态规范化：原“待验证”，因已过复核时点且未留后验证据，改为“逾期未留证”；原后续验证=待14:00验证
A15: 2026-06-05 | B15: 2026-06-05 建仓决策 | C15: 盘中复查 | D15: 13:00 | E15: 600000 | F15: 浦发银行 | G15: 做多 | H15: 买入 | I15: 16200 | J15: 9.23 | L15: 149526 | T15: 149526 | AC15: 14.9526 | AK15: 低波动稳定仓，按预设小仓验证。 | AM15: 需补审 | AN15: 逾期未留证 | AO15: 状态规范化：原“待验证”，因已过复核时点且未留后验证据，改为“逾期未留证”；原后续验证=待13:15验证
A16: 2026-06-05 | B16: 2026-06-05 13:30复查 | C16: 盘中复查 | D16: 13:32 | E16: 600000 | F16: 浦发银行 | G16: 做多 | H16: 持有，不加仓 | I16: 16200 | J16: 9.29 | L16: 150498 | R16: 206480 | S16: 999318 | T16: 150498 | AC16: 15.0498 | AK16: 持仓中最强，但分数仍49.5且只是弱势反弹，现金不追。 | AM16: 需补审 | AN16: 逾期未留证 | AO16: 补做13:30复查；原权益列迁出: daily_return_pct=-0.0682；状态规范化：原“待验证”，因已过复核时点且未留后验证据，改为“逾期未留证”；原后续验证=待14:00验证
A17: 2026-06-08 | B17: 2026-06-08 持仓 | C17: 持仓 | E17: 600519 | F17: 贵州茅台 | G17: 持有 | I17: 100 | J17: 1262.98 | K17: 1501.4004 | T17: 126298.0 | Z17: -23842.04 | AA17: -15.8799 | AC17: 12.9383 | AN17: 持仓中 | AO17: 正式模拟盘保留持仓；回测卖出未获用户确认，不作为正式模拟盘成交
A18: 2026-06-09 | B18: 2026-06-09 收盘结算 | C18: 盘中复查 | E18: 600519 | F18: 贵州茅台 | G18: 多头连续持仓 | H18: 持有/估值 | I18: 100 | J18: 1256 | L18: 125600 | R18: 849859.96 | S18: 125600 | T18: 125600 | AC18: 12.876 | AK18: 未触发用户确认卖出；只做训练/研究估值 | AM18: 需补审 | AN18: 逾期未留证 | AO18: 今日浮动盈亏-698.00；累计未实现盈亏-24540.04；账户权益975459.96。；原权益列迁出: daily_return_pct=-2.454；状态规范化：原“待验证”，因已过复核时点且未留后验证据，改为“逾期未留证”；原后续验证=次日继续复核触发、无效、止损纪律
A19: 2026-06-20 | B19: 2026-06-20 目标组合 | C19: 目标组合 | E19: 000001 | F19: 平安银行 | G19: 观察 | H19: 候选目标仓位 | I19: 0 | J19: 11.00 | T19: 39046.32 | AC19: 4.0 | AE19: STOP | AF19: defensive-training-portfolio-v1 | AG19: defensive-training-portfolio-v1 | AJ19: watch | AK19: 旧表主攻样本但13:30回落，降为小目标观察仓；只有转强且不跌回触发价才可执行。 | AO19: 目标仓位4%，不是当前成交。；原权益列迁出: end_equity=976157.96
A20: 2026-06-20 | B20: 2026-06-20 目标组合 | C20: 目标组合 | E20: 000858 | F20: 五粮液 | G20: 观察 | H20: 候选目标仓位 | I20: 0 | J20: 81.38 | T20: 39046.32 | AC20: 4.0 | AE20: STOP | AF20: defensive-training-portfolio-v1 | AG20: defensive-training-portfolio-v1 | AJ20: watch | AK20: 旧表副攻样本且复查回落，目标仓位下调；只在反弹承接重新确认后执行。 | AO20: 目标仓位4%，不是当前成交。；原权益列迁出: end_equity=976157.96
A21: 2026-06-20 | B21: 2026-06-20 目标组合 | C21: 目标组合 | E21: 300750 | F21: 宁德时代 | G21: 观察 | H21: 条件仓候选 | I21: 0 | J21: 407.67 | T21: 29284.74 | AC21: 3.0 | AE21: STOP | AF21: defensive-training-portfolio-v1 | AG21: defensive-training-portfolio-v1 | AJ21: watch | AK21: 旧表条件仓未触发，保留小目标权重；需翻红、放量、强于池子才允许执行。 | AO21: 目标仓位3%，不是当前成交。；原权益列迁出: end_equity=976157.96
A22: 2026-06-20 | B22: 2026-06-20 目标组合 | C22: 目标组合 | E22: 600000 | F22: 浦发银行 | G22: 观察 | H22: 候选目标仓位 | I22: 0 | J22: 9.29 | T22: 58569.48 | AC22: 6.0 | AE22: STOP | AF22: defensive-training-portfolio-v1 | AG22: defensive-training-portfolio-v1 | AJ22: watch | AK22: 旧表中13:30复查相对最强，但账户STOP下只能作为低波动候选；重新通过缓存/策略门禁后才允许执行。 | AO22: 目标仓位6%，不是当前成交。；原权益列迁出: end_equity=976157.96
A23: 2026-06-20 | B23: 2026-06-20 目标组合 | C23: 目标组合 | E23: 600519 | F23: 贵州茅台 | G23: 持有 | H23: 保留现有持仓，不加仓 | I23: 100 | J23: 1262.98 | T23: 126298.00 | Z23: -23842.04 | AA23: -15.8799 | AC23: 12.94 | AE23: STOP | AF23: defensive-training-portfolio-v1 | AG23: defensive-training-portfolio-v1 | AJ23: active | AK23: 连续持仓事实保留；未触发用户确认卖出，不做日结清仓；不新增仓位。 | AO23: 当前事实持仓，纳入目标组合但不加仓。；原权益列迁出: end_equity=976157.96
A24: 2026-06-20 | B24: 2026-06-20 目标组合 | C24: 目标组合 | E24: CASH | F24: 现金 | G24: 现金 | H24: 保留现金 | R24: 683310.57 | T24: 683310.57 | AC24: 70.0 | AE24: STOP | AF24: defensive-training-portfolio-v1 | AG24: defensive-training-portfolio-v1 | AJ24: active | AK24: 账户风险状态为STOP，目标组合先以现金为主，等待策略重新通过验证。 | AO24: 目标组合，不是成交；后续每日在本表更新。；原权益列迁出: end_equity=976157.96
A25: 2026-06-23 | B25: 2026-06-23 交易 | C25: 成交 | D25: 13:04 | E25: 002230 | F25: 科大讯飞 | G25: 买入 | H25: 买入 | I25: 300 | J25: 42.7013 | L25: 12810.4 | M25: 5.0 | N25: 0.0 | O25: 0.13 | P25: 5.13 | Q25: -12815.53 | AF25: diversified-paper-6-ai-v1 | AG25: diversified-paper-6-ai-v1 | AK25: 按用户要求新增AI科技股；系统风控提示高风险观察，因此仅小仓纸面训练买入 | AN25: 已成交 | AO25: 训练/研究纸面买入，不构成投资建议；若跌破42.50或无法收回MA20则优先止损/降仓复核；时间更正：原记录 12:49 为午间决策/记录时间，非A股连续竞价成交时间；纸面成交按午后可交易时段 13:04 记录。
A26: 2026-06-23 | B26: 2026-06-23 交易 | C26: 成交 | D26: 13:00 | E26: 300750 | F26: 宁德时代 | G26: 买入 | H26: 买入 | I26: 100 | J26: 401.7908 | L26: 40179.08 | M26: 12.05 | N26: 0.0 | O26: 0.4 | P26: 12.46 | Q26: -40191.54 | AF26: diversified-paper-5-v1 | AG26: diversified-paper-5-v1 | AK26: 补足至少5只纸面持仓：新能源类别，小仓训练；系统评分偏弱，仅做分散组合训练 | AN26: 已成交 | AO26: 训练/研究纸面买入，不构成投资建议；若跌破MA20且edge低于50%则复核止损；时间更正：原记录 12:45 为午间决策/记录时间，非A股连续竞价成交时间；纸面成交按午后可交易时段 13:00 记录。
A27: 2026-06-23 | B27: 2026-06-23 交易 | C27: 成交 | D27: 13:01 | E27: 600036 | F27: 招商银行 | G27: 买入 | H27: 买入 | I27: 1000 | J27: 37.7989 | L27: 37798.89 | M27: 11.34 | N27: 0.0 | O27: 0.38 | P27: 11.72 | Q27: -37810.61 | AF27: diversified-paper-5-v1 | AG27: diversified-paper-5-v1 | AK27: 补足至少5只纸面持仓：银行类别，低波动样本，小仓训练 | AN27: 已成交 | AO27: 训练/研究纸面买入，不构成投资建议；弱动能下不得加仓；时间更正：原记录 12:46 为午间决策/记录时间，非A股连续竞价成交时间；纸面成交按午后可交易时段 13:01 记录。
A28: 2026-06-23 | B28: 2026-06-23 交易 | C28: 成交 | D28: 13:03 | E28: 600941 | F28: 中国移动 | G28: 买入 | H28: 买入 | I28: 400 | J28: 90.9955 | L28: 36398.19 | M28: 10.92 | N28: 0.0 | O28: 0.36 | P28: 11.28 | Q28: -36409.47 | AF28: diversified-paper-5-v1 | AG28: diversified-paper-5-v1 | AK28: 补足至少5只纸面持仓：通信运营商类别，防守样本，小仓训练 | AN28: 已成交 | AO28: 训练/研究纸面买入，不构成投资建议；弱趋势反弹失败则退出观察；时间更正：原记录 12:48 为午间决策/记录时间，非A股连续竞价成交时间；纸面成交按午后可交易时段 13:03 记录。
A29: 2026-06-23 | B29: 2026-06-23 交易 | C29: 成交 | D29: 13:02 | E29: 688981 | F29: 中芯国际 | G29: 买入 | H29: 买入 | I29: 200 | J29: 144.092 | L29: 28818.4 | M29: 8.65 | N29: 0.0 | O29: 0.29 | P29: 8.93 | Q29: -28827.34 | AF29: diversified-paper-5-v1 | AG29: diversified-paper-5-v1 | AK29: 补足至少5只纸面持仓：半导体硬科技类别，复权一致性保守，小仓训练 | AN29: 已成交 | AO29: 训练/研究纸面买入，不构成投资建议；高波动和普通日线数据要求更严止损；时间更正：原记录 12:47 为午间决策/记录时间，非A股连续竞价成交时间；纸面成交按午后可交易时段 13:02 记录。
A30: 2026-06-23 | B30: 2026-06-23 组合汇总 | C30: 组合汇总 | R30: 693805.47 | S30: 281629.0 | U30: 975434.47 | V30: 975434.47 | W30: 0.0 | X30: 0.0 | AB30: 28.8722 | AD30: -2.4566 | AE30: OK | AO30: 按用户要求在5类组合基础上新增AI科技股002230；已更正纸面成交时间到A股午后连续竞价时段；每日回测纳入后续自动化；训练/研究，不构成投资建议。
A31: 2026-06-23 | B31: 2026-06-23 每日回测 | C31: 回测 | D31: 12:50 | E31: PORTFOLIO | F31: 当前6股纸面组合 | G31: 研究 | H31: 每日组合回测 | I31: 6 | AB31: 59.93 | AD31: -10.8126 | AE31: BACKTEST_DD_OVER_STOP | AF31: daily-portfolio-backtest-v1 | AG31: daily-portfolio-backtest-v1 | AH31: backtest.py default score | AI31: T+1 daily rebalance; prior-close signal; next-open execution; costs/slippage included | AJ31: needs_daily_tracking | AK31: 用户要求坚持每日回测；本行按A股T+1日频调仓口径更新，区分回测信号与真实纸面成交。 | AL31: 训练/研究：检验当前纸面持仓池在统一策略下的历史表现。 | AM31: 2026-06-24 | AN31: 已完成 | AO31: 输出目录 trading-journal/backtests/2026-06-23-daily-portfolio；T+1日频回测，非高频；期末权益1086989.62，总收益8.6990%，最大回撤10.8126%，Sharpe0.7550，交易314次，回测当前持仓600036/600941。；回测初始资金1000000.0；回测期末权益1086989.62
A32: 2026-06-23 | B32: 2026-06-23 持仓 | C32: 持仓 | E32: 002230 | F32: 科大讯飞 | G32: 持有 | I32: 300 | J32: 42.68 | K32: 42.7184 | T32: 12804.0 | Z32: -11.53 | AA32: -0.09 | AC32: 1.3126 | AN32: 持仓中
A33: 2026-06-23 | B33: 2026-06-23 持仓 | C33: 持仓 | E33: 300750 | F33: 宁德时代 | G33: 持有 | I33: 100 | J33: 401.59 | K33: 401.9154 | T33: 40159.0 | Z33: -32.54 | AA33: -0.081 | AC33: 4.117 | AN33: 持仓中
A34: 2026-06-23 | B34: 2026-06-23 持仓 | C34: 持仓 | E34: 600036 | F34: 招商银行 | G34: 持有 | I34: 1000 | J34: 37.78 | K34: 37.8106 | T34: 37780.0 | Z34: -30.61 | AA34: -0.081 | AC34: 3.8731 | AN34: 持仓中
A35: 2026-06-23 | B35: 2026-06-23 持仓 | C35: 持仓 | E35: 600519 | F35: 贵州茅台 | G35: 持有 | I35: 100 | J35: 1257.02 | K35: 1501.4004 | T35: 125702.0 | Z35: -24438.04 | AA35: -16.2768 | AC35: 12.8868 | AN35: 持仓中
A36: 2026-06-23 | B36: 2026-06-23 持仓 | C36: 持仓 | E36: 600941 | F36: 中国移动 | G36: 持有 | I36: 400 | J36: 90.95 | K36: 91.0237 | T36: 36380.0 | Z36: -29.47 | AA36: -0.0809 | AC36: 3.7296 | AN36: 持仓中
A37: 2026-06-23 | B37: 2026-06-23 持仓 | C37: 持仓 | E37: 688981 | F37: 中芯国际 | G37: 持有 | I37: 200 | J37: 144.02 | K37: 144.1367 | T37: 28804.0 | Z37: -23.33 | AA37: -0.0809 | AC37: 2.9529 | AN37: 持仓中
A38: 2026-06-24 | B38: 2026-06-24 交易 | C38: 成交 | D38: 10:07 | E38: 300750 | F38: 宁德时代 | G38: 卖出 | H38: 卖出 | I38: 30 | J38: 389.755 | L38: 11692.65 | M38: 5.0 | N38: 5.85 | O38: 0.12 | P38: 10.96 | Q38: 11681.69 | AF38: continue-frequency-20260624-v1 | AG38: continue-frequency-20260624-v1 | AK38: 按用户要求延续昨日交易频次；300750评分36.6、弱于MA20/MA60，纸面减仓验证止损纪律 | AN38: 已成交 | AO38: 训练/研究纸面卖出，不构成投资建议；保留70股，10:30复核是否收回390和今开392。
A39: 2026-06-24 | B39: 2026-06-24 交易 | C39: 成交 | D39: 10:08 | E39: 600036 | F39: 招商银行 | G39: 卖出 | H39: 卖出 | I39: 300 | J39: 37.0815 | L39: 11124.44 | M39: 5.0 | N39: 5.56 | O39: 0.11 | P39: 10.67 | Q39: 11113.76 | AF39: continue-frequency-20260624-v1 | AG39: continue-frequency-20260624-v1 | AK39: 按用户要求延续昨日交易频次；600036早盘-0.80%且弱于今开，低波动样本纸面降仓 | AN39: 已成交 | AO39: 训练/研究纸面卖出，不构成投资建议；保留700股，若10:30不能收回37.49则不回补。
A40: 2026-06-24 | B40: 2026-06-24 交易 | C40: 成交 | D40: 10:06 | E40: 600519 | F40: 贵州茅台 | G40: 卖出 | H40: 卖出 | I40: 30 | J40: 1215.2721 | L40: 36458.16 | M40: 10.94 | N40: 18.23 | O40: 0.36 | P40: 29.53 | Q40: 36428.63 | AF40: continue-frequency-20260624-v1 | AG40: continue-frequency-20260624-v1 | AK40: 按用户要求延续昨日交易频次；600519评分39且近120日回撤超20%，纸面减仓控制单票权重 | AN40: 已成交 | AO40: 训练/研究纸面卖出，不构成投资建议；保留70股连续持仓，10:30复核是否收回今开1222.65，否则继续降风险。
...

Sheet 配置表
A1: config_key | B1: config_value | C1: description
A2: INITIAL_CAPITAL | B2: 1000000 | C2: 初始训练资金
A3: MAX_DRAWDOWN_STOP | B3: 0.05 | C3: 触发 STOP 的当前回撤阈值
A4: MAX_DRAWDOWN_WARNING | B4: 0.03 | C4: 触发 WARNING 的当前回撤阈值
A5: DEFAULT_COMMISSION_RATE | B5: 0.0003 | C5: 默认佣金率
A6: DEFAULT_STAMP_TAX_RATE | B6: 0.0005 | C6: 当前账本卖出印花税率
A7: DEFAULT_TRANSFER_RATE | B7: 1e-05 | C7: 过户/经手费率占位
A8: MIN_TRADE_LOT | B8: 100 | C8: A股最小交易单位
A9: ODD_LOT_ALLOWED | B9: FALSE | C9: 是否允许卖出制造零股

Sheet 交易订单表
A1: order_id | B1: trade_date | C1: symbol | D1: name | E1: side | F1: order_type | G1: quantity | H1: limit_price | I1: exec_price | J1: exec_time | K1: status | L1: strategy_id | M1: signal_score | N1: reason | O1: plan_id | P1: created_at
A2: T20260623001 | B2: 2026-06-23 | C2: 002230 | D2: 科大讯飞 | E2: BUY | F2: LIMIT | G2: 300 | H2: 42.7013 | I2: 42.7013 | J2: 13:04 | K2: FILLED | L2: diversified-paper-6-ai-v1 | N2: 按用户要求新增AI科技股；系统风控提示高风险观察，因此仅小仓纸面训练买入 | P2: 2026-06-23 13:04
A3: T20260623002 | B3: 2026-06-23 | C3: 300750 | D3: 宁德时代 | E3: BUY | F3: LIMIT | G3: 100 | H3: 401.7908 | I3: 401.7908 | J3: 13:00 | K3: FILLED | L3: diversified-paper-5-v1 | N3: 补足至少5只纸面持仓：新能源类别，小仓训练；系统评分偏弱，仅做分散组合训练 | P3: 2026-06-23 13:00
A4: T20260623003 | B4: 2026-06-23 | C4: 600036 | D4: 招商银行 | E4: BUY | F4: LIMIT | G4: 1000 | H4: 37.7989 | I4: 37.7989 | J4: 13:01 | K4: FILLED | L4: diversified-paper-5-v1 | N4: 补足至少5只纸面持仓：银行类别，低波动样本，小仓训练 | P4: 2026-06-23 13:01
A5: T20260623004 | B5: 2026-06-23 | C5: 600941 | D5: 中国移动 | E5: BUY | F5: LIMIT | G5: 400 | H5: 90.9955 | I5: 90.9955 | J5: 13:03 | K5: FILLED | L5: diversified-paper-5-v1 | N5: 补足至少5只纸面持仓：通信运营商类别，防守样本，小仓训练 | P5: 2026-06-23 13:03
A6: T20260623005 | B6: 2026-06-23 | C6: 688981 | D6: 中芯国际 | E6: BUY | F6: LIMIT | G6: 200 | H6: 144.092 | I6: 144.092 | J6: 13:02 | K6: FILLED | L6: diversified-paper-5-v1 | N6: 补足至少5只纸面持仓：半导体硬科技类别，复权一致性保守，小仓训练 | P6: 2026-06-23 13:02
A7: T20260624006 | B7: 2026-06-24 | C7: 300750 | D7: 宁德时代 | E7: SELL | F7: STOP | G7: 30 | I7: 389.755 | J7: 10:07 | K7: FILLED | L7: continue-frequency-20260624-v1 | M7: 36.6 | N7: 按用户要求延续昨日交易频次；300750评分36.6、弱于MA20/MA60，纸面减仓验证止损纪律 | P7: 2026-06-24 10:07
A8: T20260624007 | B8: 2026-06-24 | C8: 600036 | D8: 招商银行 | E8: SELL | F8: LIMIT | G8: 300 | I8: 37.0815 | J8: 10:08 | K8: FILLED | L8: continue-frequency-20260624-v1 | N8: 按用户要求延续昨日交易频次；600036早盘-0.80%且弱于今开，低波动样本纸面降仓 | P8: 2026-06-24 10:08
A9: T20260624008 | B9: 2026-06-24 | C9: 600519 | D9: 贵州茅台 | E9: SELL | F9: LIMIT | G9: 30 | I9: 1215.2721 | J9: 10:06 | K9: FILLED | L9: continue-frequency-20260624-v1 | M9: 39 | N9: 按用户要求延续昨日交易频次；600519评分39且近120日回撤超20%，纸面减仓控制单票权重 | O9: P20260605001 | P9: 2026-06-24 10:06
A10: T20260624009 | B10: 2026-06-24 | C10: 600941 | D10: 中国移动 | E10: SELL | F10: LIMIT | G10: 100 | I10: 89.6552 | J10: 10:09 | K10: FILLED | L10: continue-frequency-20260624-v1 | N10: 按用户要求延续昨日交易频次；600941早盘-0.91%且跌破昨日成本，纸面降低防守仓 | P10: 2026-06-24 10:09
A11: T20260624010 | B11: 2026-06-24 | C11: 688981 | D11: 中芯国际 | E11: BUY | F11: LIMIT | G11: 100 | H11: 148.7443 | I11: 148.7443 | J11: 10:10 | K11: FILLED | L11: continue-frequency-20260624-v1 | N11: 按用户要求延续昨日交易频次；688981早盘+4.92%为当前组合唯一明显转强样本，纸面小幅加仓验证强者留存 | P11: 2026-06-24 10:10
A12: T20260626011 | B12: 2026-06-26 | C12: 002230 | D12: 未知 | E12: SELL | F12: LIMIT | G12: 100 | I12: 40.3498 | J12: 09:30 | K12: FILLED | L12: score-standard-v1 | M12: 38.5 | N12: 评分 38.5 低于退出阈值 45.0，按分层减仓 33% 处理 | O12: P20260625011 | P12: 2026-06-26 09:30
A13: T20260626012 | B13: 2026-06-26 | C13: 600036 | D13: 未知 | E13: SELL | F13: LIMIT | G13: 200 | I13: 36.0919 | J13: 09:30 | K13: FILLED | L13: score-standard-v1 | M13: 42.9 | N13: 评分 42.9 低于退出阈值 45.0，按分层减仓 33% 处理 | P13: 2026-06-26 09:30
A14: T20260626013 | B14: 2026-06-26 | C14: 600519 | D14: 贵州茅台 | E14: SELL | F14: LIMIT | G14: 70 | I14: 1185.397 | J14: 09:30 | K14: FILLED | L14: score-standard-v1 | M14: 38.6 | N14: 评分 38.6 低于退出阈值 45.0，按分层减仓 33% 处理 | O14: P20260605001 | P14: 2026-06-26 09:30
A15: T20260630014 | B15: 2026-06-30 | C15: 002230 | D15: 未知 | E15: SELL | F15: LIMIT | G15: 100 | I15: 40.5097 | J15: 09:30 | K15: FILLED | L15: score-standard-v1 | M15: 30.5 | N15: 评分 30.5 低于退出阈值 45.0，按分层减仓 33% 处理 | O15: P20260625011 | P15: 2026-06-30 09:30
A16: T20260630015 | B16: 2026-06-30 | C16: 300750 | D16: 宁德时代 | E16: SELL | F16: LIMIT | G16: 70 | I16: 392.1738 | J16: 09:30 | K16: FILLED | L16: score-standard-v1 | M16: 28.2 | N16: 评分 28.2 低于退出阈值 45.0，按分层减仓 33% 处理 | P16: 2026-06-30 09:30
A17: T20260630016 | B17: 2026-06-30 | C17: 600036 | D17: 未知 | E17: SELL | F17: LIMIT | G17: 100 | I17: 35.912 | J17: 09:30 | K17: FILLED | L17: score-standard-v1 | M17: 42.6 | N17: 评分 42.6 低于退出阈值 45.0，按分层减仓 33% 处理 | P17: 2026-06-30 09:30

Sheet 持仓明细表
A1: date | B1: symbol | C1: name | D1: quantity | E1: avg_cost | F1: last_price | G1: market_value | H1: unrealized_pnl | I1: unrealized_pnl_% | J1: weight_% | K1: cost_basis | L1: note
A2: 2026-06-08 | B2: 600519 | C2: 贵州茅台 | D2: 100 | E2: 1501.4004 | F2: 1262.98 | G2: =D2*F2 | H2: =D2*(F2-E2) | I2: =IFERROR(H2/K2,"") | J2: 0.129383 | K2: =D2*E2 | L2: 正式模拟盘保留持仓；回测卖出未获用户确认，不作为正式模拟盘成交
A3: 2026-06-23 | B3: 002230 | C3: 科大讯飞 | D3: 300 | E3: 42.7184 | F3: 42.68 | G3: =D3*F3 | H3: =D3*(F3-E3) | I3: =IFERROR(H3/K3,"") | J3: 0.013126 | K3: =D3*E3
A4: 2026-06-23 | B4: 300750 | C4: 宁德时代 | D4: 100 | E4: 401.9154 | F4: 401.59 | G4: =D4*F4 | H4: =D4*(F4-E4) | I4: =IFERROR(H4/K4,"") | J4: 0.04117 | K4: =D4*E4
A5: 2026-06-23 | B5: 600036 | C5: 招商银行 | D5: 1000 | E5: 37.8106 | F5: 37.78 | G5: =D5*F5 | H5: =D5*(F5-E5) | I5: =IFERROR(H5/K5,"") | J5: 0.038731 | K5: =D5*E5
A6: 2026-06-23 | B6: 600519 | C6: 贵州茅台 | D6: 100 | E6: 1501.4004 | F6: 1257.02 | G6: =D6*F6 | H6: =D6*(F6-E6) | I6: =IFERROR(H6/K6,"") | J6: 0.128868 | K6: =D6*E6
A7: 2026-06-23 | B7: 600941 | C7: 中国移动 | D7: 400 | E7: 91.0237 | F7: 90.95 | G7: =D7*F7 | H7: =D7*(F7-E7) | I7: =IFERROR(H7/K7,"") | J7: 0.037296 | K7: =D7*E7
A8: 2026-06-23 | B8: 688981 | C8: 中芯国际 | D8: 200 | E8: 144.1367 | F8: 144.02 | G8: =D8*F8 | H8: =D8*(F8-E8) | I8: =IFERROR(H8/K8,"") | J8: 0.029529 | K8: =D8*E8
A9: 2026-06-24 | B9: 002230 | C9: 科大讯飞 | D9: 300 | E9: 42.7184 | F9: 42.01 | G9: =D9*F9 | H9: =D9*(F9-E9) | I9: =IFERROR(H9/K9,"") | J9: 0.012998 | K9: =D9*E9
A10: 2026-06-24 | B10: 300750 | C10: 宁德时代 | D10: 70 | E10: 401.9154 | F10: 389.95 | G10: =D10*F10 | H10: =D10*(F10-E10) | I10: =IFERROR(H10/K10,"") | J10: 0.028152 | K10: =D10*E10
A11: 2026-06-24 | B11: 600036 | C11: 招商银行 | D11: 700 | E11: 37.8106 | F11: 37.1 | G11: =D11*F11 | H11: =D11*(F11-E11) | I11: =IFERROR(H11/K11,"") | J11: 0.026784 | K11: =D11*E11
A12: 2026-06-24 | B12: 600519 | C12: 贵州茅台 | D12: 70 | E12: 1501.4004 | F12: 1215.88 | G12: =D12*F12 | H12: =D12*(F12-E12) | I12: =IFERROR(H12/K12,"") | J12: 0.08778 | K12: =D12*E12
A13: 2026-06-24 | B13: 600941 | C13: 中国移动 | D13: 300 | E13: 91.0237 | F13: 89.7 | G13: =D13*F13 | H13: =D13*(F13-E13) | I13: =IFERROR(H13/K13,"") | J13: 0.027754 | K13: =D13*E13
A14: 2026-06-24 | B14: 688981 | C14: 中芯国际 | D14: 300 | E14: 145.6897 | F14: 148.67 | G14: =D14*F14 | H14: =D14*(F14-E14) | I14: =IFERROR(H14/K14,"") | J14: 0.045999 | K14: =D14*E14
... A25: 2026-06-27 | B25: 688981 | C25: 中芯国际 | D25: 300 | E25: 145.6897 | F25: 155.55 | G25: =D25*F25 | H25: =D25*(F25-E25) | I25: =IFERROR(H25/K25,"") | J25: 0.048204 | K25: =D25*E25

Sheet 每日账户汇总
A1: date | B1: cash | C1: total_market_value | D1: total_equity | E1: daily_pnl | F1: daily_return_% | G1: cumulative_return_% | H1: max_drawdown_% | I1: current_drawdown_% | J1: var_95% | K1: exposure_% | L1: risk_status | M1: leverage | N1: note
A2: 2026-06-23 | B2: 693805.47 | C2: 281629 | D2: =B2+C2 | E2: 0 | F2: 0 | G2: =IFERROR(D2/'配置表'!$B$2-1,"") | H2: -0.024566 | I2: =IFERROR(D2/MAX($D$2:D2)-1,"") | K2: =IFERROR(C2/D2,"") | L2: =IF(I2<=-'配置表'!$B$3,"STOP",IF(I2<=-'配置表'!$B$4,"WARNING","OK")) | M2: 0 | N2: 按用户要求在5类组合基础上新增AI科技股002230；已更正纸面成交时间到A股午后连续竞价时段；每日回测纳入后续自动化；训练/研究，不构成投资建议。
A3: 2026-06-24 | B3: 747105.91 | C3: 222492.1 | D3: =B3+C3 | E3: =D3-D2 | F3: =IFERROR(E3/D2,"") | G3: =IFERROR(D3/'配置表'!$B$2-1,"") | H3: -0.030402 | I3: =IFERROR(D3/MAX($D$2:D3)-1,"") | K3: =IFERROR(C3/D3,"") | L3: =IF(I3<=-'配置表'!$B$3,"STOP",IF(I3<=-'配置表'!$B$4,"WARNING","OK")) | M3: 0 | N3: 按用户要求延续昨日5笔纸面交易频次：弱势持仓降风险，唯一强势688981小幅加仓；训练/研究，不构成投资建议；10:30复核收回今开和加仓有效性。
A4: 2026-06-25 | B4: 747105.91 | C4: 224213 | D4: =B4+C4 | E4: =D4-D3 | F4: =IFERROR(E4/D3,"") | G4: =IFERROR(D4/'配置表'!$B$2-1,"") | H4: -0.028681 | I4: =IFERROR(D4/MAX($D$2:D4)-1,"") | K4: =IFERROR(C4/D4,"") | L4: =IF(I4<=-'配置表'!$B$3,"STOP",IF(I4<=-'配置表'!$B$4,"WARNING","OK")) | M4: 0 | N4: 盘后每日风险监控：6只纸面持仓估值更新；无新增纸面成交；T+1可卖仓位为既有持仓全部可卖，今日无买入；600519仍弱于MA5/MA10/MA20/MA60且近120日回撤超20%，只做分层减仓纪律观察；300750修复但未站稳MA20；688981为普通日线回退，复权一致性需二次确认；训练/研究，不构成投资建议。；已按上一交易日2026-06-24期末权益修正当日盈亏口径。
A5: 2026-06-27 | B5: 841254.12 | C5: 126814.5 | D5: =B5+C5 | E5: =D5-D4 | F5: =IFERROR(E5/D4,"") | G5: =IFERROR(D5/'配置表'!$B$2-1,"") | H5: -0.031931 | I5: =IFERROR(D5/MAX($D$2:D5)-1,"") | K5: =IFERROR(C5/D5,"") | L5: =IF(I5<=-'配置表'!$B$3,"STOP",IF(I5<=-'配置表'!$B$4,"WARNING","OK")) | M5: 0 | N5: daily_pipeline 纸面收盘结算；非真实交易

Sheet 策略信号日志
A1: signal_id | B1: signal_time | C1: symbol | D1: strategy_id | E1: signal_type | F1: score | G1: entry_threshold | H1: exit_threshold | I1: suggested_action | J1: actual_action | K1: valid | L1: reason
A2: S20260605001 | B2: 2026-06-05 13:00 | C2: 000001 | D2: 纸面买入主仓 | E2: ENTRY | I2: 13:00若强势延续则纸面买入 | J2: 13:00若强势延续则纸面买入 | K2: REVIEW | L2: 维持强于池子；不跌回11.02；量能不恶化
A3: S20260605002 | B3: 2026-06-05 13:00 | C3: 000858 | D3: 纸面买入副仓 | E3: ENTRY | I3: 13:00只在反弹延续时纸面买入 | J3: 13:00只在反弹延续时纸面买入 | K3: REVIEW | L3: 不破81.52；反弹有承接；不能冲高回落
A4: S20260605003 | B4: 2026-06-05 13:00 | C4: 600000 | D4: 纸面买入小仓 | E4: ENTRY | I4: 13:00小仓纸面验证 | J4: 13:00小仓纸面验证 | K4: REVIEW | L4: 维持9.23上方；波动低；不弱于银行样本
A5: S20260605004 | B5: 2026-06-05 | C5: 600519 | D5: 不买/对照 | E5: ENTRY | I5: 连续持仓估值，不日结卖出 | J5: 连续持仓估值，不日结卖出 | K5: REVIEW | L5: 无
A6: S20260605005 | B6: 2026-06-05 13:00 | E6: HOLD | I6: 13:00纸面建仓完成 | J6: 13:00纸面建仓完成 | K6: REVIEW | L6: 历史Excel盘中组合快照，非正式日结权益行
A7: S20260605006 | B7: 2026-06-05 13:32 | E7: HOLD | I7: 13:30复查：不加仓，保留现金 | J7: 13:30复查：不加仓，保留现金 | K7: REVIEW | L7: 历史Excel盘中组合快照，非正式日结权益行
A8: S20260605007 | B8: 2026-06-05 13:00 | C8: 000001 | E8: ENTRY | I8: 买入 | J8: 买入 | K8: REVIEW | L8: 仍为观察池中唯一尝试转强样本，执行预设主攻仓。
A9: S20260605008 | B9: 2026-06-05 13:32 | C9: 000001 | E9: HOLD | I9: 持有，不加仓 | J9: 持有，不加仓 | K9: REVIEW | L9: 较13:00买入价回落，暂不触发止损，但不能加仓。
A10: S20260605009 | B10: 2026-06-05 13:00 | C10: 000858 | E10: ENTRY | F10: 13 | I10: 买入 | J10: 买入 | K10: REVIEW | L10: 评分最高但仍弱势，按预设只给副攻反弹仓。
A11: S20260605010 | B11: 2026-06-05 13:32 | C11: 000858 | E11: HOLD | I11: 持有，不加仓 | J11: 持有，不加仓 | K11: REVIEW | L11: 较13:00买入价回落，暂不触发止损，但不能加仓。
A12: S20260605011 | B12: 2026-06-05 13:00 | C12: 300750 | E12: HOLD | I12: 观察 | J12: 观察 | K12: REVIEW | L12: 13:00仅持平，未显示明显转强，条件仓不触发。
A13: S20260605012 | B13: 2026-06-05 13:32 | C13: 300750 | E13: HOLD | I13: 继续观察 | J13: 继续观察 | K13: REVIEW | L13: 条件仓仍未触发。
A14: S20260605013 | B14: 2026-06-05 13:00 | C14: 600000 | E14: ENTRY | I14: 买入 | J14: 买入 | K14: REVIEW | L14: 低波动稳定仓，按预设小仓验证。
A15: S20260605014 | B15: 2026-06-05 13:32 | C15: 600000 | E15: HOLD | I15: 持有，不加仓 | J15: 持有，不加仓 | K15: REVIEW | L15: 持仓中最强，但分数仍49.5且只是弱势反弹，现金不追。
A16: S20260609015 | B16: 2026-06-09 | C16: 600519 | E16: HOLD | I16: 持有/估值 | J16: 持有/估值 | K16: REVIEW | L16: 未触发用户确认卖出；只做训练/研究估值
A17: S20260623016 | B17: 2026-06-23 12:50 | C17: PORTFOLIO | D17: daily-portfolio-backtest-v1 | E17: RESEARCH | I17: 每日组合回测 | J17: 每日组合回测 | K17: TRUE | L17: 用户要求坚持每日回测；本行按A股T+1日频调仓口径更新，区分回测信号与真实纸面成交。
A18: S20260625017 | B18: 2026-06-25 15:40 | C18: 002230 | D18: score-standard-v1 | E18: EXIT | F18: 43.1 | G18: 58 | H18: 45 | I18: 明日按回测策略分层减仓计划 | J18: 明日按回测策略分层减仓计划 | K18: REVIEW | L18: 复用回测交易策略：评分43.1低于退出阈值45.0，生成分层减仓100股计划；15:00后不得补记今日成交，计划最早下一交易日09:30后按有效交易时段执行。
A19: S20260625018 | B19: 2026-06-25 15:40 | C19: PORTFOLIO | D19: score-standard-v1 | E19: HOLD | F19: 1 | I19: 启用回测策略为纸面执行策略 | J19: 启用回测策略为纸面执行策略 | K19: TRUE | L19: 用户明确指出可以复用回测交易策略，修正此前仅风险监控不交易的保守解释；后续纸面执行以score-standard-v1为默认。
A20: S20260630019 | B20: 2026-06-30 10:02 | C20: 603019 | D20: shenzhen-intern-trail-v1 | E20: ENTRY | I20: 深圳实习生选股观察计划 | J20: 深圳实习生选股观察计划 | K20: REVIEW | L20: 同板块已有涨停个股，龙二跟随：A类突破买点; 新闻热度 3.0; 通过：量能4/11/117多头排列，股价均线多头排列 (MA5>MA10>MA20)，大单占比 15.8%

Sheet 审计与修正记录
A1: audit_id | B1: audit_date | C1: issue_type | D1: description | E1: affected_order_id | F1: affected_date | G1: status | H1: fix_action | I1: fix_date | J1: verified_by | K1: raw_detail
A2: A20260625001 | B2: 2026-06-25 | C2: invalid_sell_lot | D2: 300750 卖出 30 股非整手且未清仓 | E2: T20260624-300750 | F2: 2026-06-24 | G2: OPEN | H2: 后续执行不得制造零股；不足一手时仅允许清仓或继续持有。 | J2: system | K2: {"type": "invalid_sell_lot", "csv_line": 38, "date": "2026-06-24", "symbol": "300750", "quantity": 30, "remaining": 70}
A3: A20260625002 | B3: 2026-06-25 | C3: odd_lot_remainder | D3: 300750 卖出后剩余 70 股零股 | E3: T20260624-300750 | F3: 2026-06-24 | G3: OPEN | H3: 后续执行不得制造零股；不足一手时仅允许清仓或继续持有。 | J3: system | K3: {"type": "odd_lot_remainder", "csv_line": 38, "date": "2026-06-24", "symbol": "300750", "quantity": 30, "remaining": 70}
A4: A20260625003 | B4: 2026-06-25 | C4: invalid_sell_lot | D4: 600519 卖出 30 股非整手且未清仓 | E4: T20260624-600519 | F4: 2026-06-24 | G4: OPEN | H4: 后续执行不得制造零股；不足一手时仅允许清仓或继续持有。 | J4: system | K4: {"type": "invalid_sell_lot", "csv_line": 40, "date": "2026-06-24", "symbol": "600519", "quantity": 30, "remaining": 70}
A5: A20260625004 | B5: 2026-06-25 | C5: odd_lot_remainder | D5: 600519 卖出后剩余 70 股零股 | E5: T20260624-600519 | F5: 2026-06-24 | G5: OPEN | H5: 后续执行不得制造零股；不足一手时仅允许清仓或继续持有。 | J5: system | K5: {"type": "odd_lot_remainder", "csv_line": 40, "date": "2026-06-24", "symbol": "600519", "quantity": 30, "remaining": 70}
A6: A20260626005 | B6: 2026-06-26 | C6: invalid_sell_lot | D6: 300750 卖出 30 股非整手且未清仓 | E6: T20260624-300750 | F6: 2026-06-24 | G6: OPEN | H6: 后续执行不得制造零股；不足一手时仅允许清仓或继续持有。 | J6: system | K6: {"type": "invalid_sell_lot", "csv_line": 38, "date": "2026-06-24", "symbol": "300750", "quantity": 30, "remaining": 70}
A7: A20260626006 | B7: 2026-06-26 | C7: odd_lot_remainder | D7: 300750 卖出后剩余 70 股零股 | E7: T20260624-300750 | F7: 2026-06-24 | G7: OPEN | H7: 后续执行不得制造零股；不足一手时仅允许清仓或继续持有。 | J7: system | K7: {"type": "odd_lot_remainder", "csv_line": 38, "date": "2026-06-24", "symbol": "300750", "quantity": 30, "remaining": 70}
A8: A20260626007 | B8: 2026-06-26 | C8: invalid_sell_lot | D8: 600519 卖出 30 股非整手且未清仓 | E8: T20260624-600519 | F8: 2026-06-24 | G8: OPEN | H8: 后续执行不得制造零股；不足一手时仅允许清仓或继续持有。 | J8: system | K8: {"type": "invalid_sell_lot", "csv_line": 40, "date": "2026-06-24", "symbol": "600519", "quantity": 30, "remaining": 70}
A9: A20260626008 | B9: 2026-06-26 | C9: odd_lot_remainder | D9: 600519 卖出后剩余 70 股零股 | E9: T20260624-600519 | F9: 2026-06-24 | G9: OPEN | H9: 后续执行不得制造零股；不足一手时仅允许清仓或继续持有。 | J9: system | K9: {"type": "odd_lot_remainder", "csv_line": 40, "date": "2026-06-24", "symbol": "600519", "quantity": 30, "remaining": 70}
A10: A20260627009 | B10: 2026-06-27 | C10: invalid_sell_lot | D10: 600519 卖出 30 股非整手且未清仓 | E10: T20260624-600519 | F10: 2026-06-24 | G10: OPEN | H10: 后续执行不得制造零股；不足一手时仅允许清仓或继续持有。 | J10: system | K10: {"type": "invalid_sell_lot", "csv_line": 40, "date": "2026-06-24", "symbol": "600519", "quantity": 30, "remaining": 70}
A11: A20260627010 | B11: 2026-06-27 | C11: odd_lot_remainder | D11: 600519 卖出后剩余 70 股零股 | E11: T20260624-600519 | F11: 2026-06-24 | G11: OPEN | H11: 后续执行不得制造零股；不足一手时仅允许清仓或继续持有。 | J11: system | K11: {"type": "odd_lot_remainder", "csv_line": 40, "date": "2026-06-24", "symbol": "600519", "quantity": 30, "remaining": 70}
A12: A20260627011 | B12: 2026-06-27 | C12: invalid_sell_lot | D12: 300750 卖出 30 股非整手且未清仓 | E12: T20260624-300750 | F12: 2026-06-24 | G12: OPEN | H12: 后续执行不得制造零股；不足一手时仅允许清仓或继续持有。 | J12: system | K12: {"type": "invalid_sell_lot", "csv_line": 38, "date": "2026-06-24", "symbol": "300750", "quantity": 30, "remaining": 70}
A13: A20260627012 | B13: 2026-06-27 | C13: odd_lot_remainder | D13: 300750 卖出后剩余 70 股零股 | E13: T20260624-300750 | F13: 2026-06-24 | G13: OPEN | H13: 后续执行不得制造零股；不足一手时仅允许清仓或继续持有。 | J13: system | K13: {"type": "odd_lot_remainder", "csv_line": 38, "date": "2026-06-24", "symbol": "300750", "quantity": 30, "remaining": 70}
... A21: A20260630020 | B21: 2026-06-30 | C21: odd_lot_remainder | D21: 300750 卖出后剩余 70 股零股 | E21: T20260624-300750 | F21: 2026-06-24 | G21: OPEN | H21: 后续执行不得制造零股；不足一手时仅允许清仓或继续持有。 | J21: system | K21: {"type": "odd_lot_remainder", "csv_line": 38, "date": "2026-06-24", "symbol": "300750", "quantity": 30, "remaining": 70}

Sheet 每日流程检查
A1: 日期 | B1: 检查点 | C1: 截止时间 | D1: 状态 | E1: 完成/补登记时间 | F1: 证据 | G1: 说明
A2: 2026-06-24 | B2: preopen_plan | C2: 08:50 | D2: overdue | F2: daily log / preopen pipeline record | G2: 盘前计划、观察池、无效条件。
A3: 2026-06-24 | B3: open_snapshot | C3: 09:40 | D3: done | E3: 2026-06-24T13:28:09 | F3: data-check outputs: 600519/300750/002230/600036/600941/688981 realtime fallback | G3: 补登记：09:31-10:05 已顺序取数并记录行情链路
A4: 2026-06-24 | B4: morning_review | C4: 10:30 | D4: done | E4: 2026-06-24T13:28:09 | F4: 交易总表 2026-06-24 TRADE rows 10:06-10:10; automation memory a lines 11-16 | G4: 补登记：按昨日频次完成5笔纸面训练交易并复核弱强
A5: 2026-06-24 | B5: midday_plan | C5: 12:10 | D5: overdue | F5: midday pipeline record / daily log | G5: 上午结果和下午执行计划。
A6: 2026-06-24 | B6: afternoon_review | C6: 14:00 | D6: pending | F6: afternoon pipeline record / intraday check row | G6: 午后加减仓或继续观察复核。
A7: 2026-06-24 | B7: close_settlement | C7: 15:20 | D7: done | E7: 2026-06-24T13:28:09 | F7: 交易总表 2026-06-24 DAY_SUMMARY; equity=969598.01 | G7: 盘中结算已完成；若收盘后需再按收盘价重结算
A8: 2026-06-24 | B8: post_close_audit | C8: 16:30 | D8: pending | F8: pipeline_review / ops report | G8: 审计缺失阶段、失败链路和次日动作。
A9: 2026-06-26 | B9: preopen_plan | C9: 08:50 | D9: overdue | F9: daily log / preopen pipeline record | G9: 盘前计划、观察池、无效条件。
A10: 2026-06-26 | B10: open_snapshot | C10: 09:40 | D10: done | E10: 2026-06-26T09:42:49 | F10: /Users/hanlinye/Desktop/vibe 作品集/股票量化交易系统/trading-journal/pipeline-runs/2026-06-26/open.json | G10: pipeline open ok
A11: 2026-06-26 | B11: morning_review | C11: 10:30 | D11: pending | F11: manual review / intraday check row | G11: 复核早盘触发、无效、止损纪律。
A12: 2026-06-26 | B12: midday_plan | C12: 12:10 | D12: pending | F12: midday pipeline record / daily log | G12: 上午结果和下午执行计划。
A13: 2026-06-26 | B13: afternoon_review | C13: 14:00 | D13: pending | F13: afternoon pipeline record / intraday check row | G13: 午后加减仓或继续观察复核。
A14: 2026-06-26 | B14: close_settlement | C14: 15:20 | D14: pending | F14: DAY_SUMMARY / close pipeline record | G14: 结算权益、现金、持仓、盈亏和风险状态。
A15: 2026-06-26 | B15: post_close_audit | C15: 16:30 | D15: pending | F15: pipeline_review / ops report | G15: 审计缺失阶段、失败链路和次日动作。
A16: 2026-06-27 | B16: preopen_plan | C16: 08:50 | D16: overdue | F16: daily log / preopen pipeline record | G16: 盘前计划、观察池、无效条件。
A17: 2026-06-27 | B17: open_snapshot | C17: 09:40 | D17: overdue | F17: open pipeline record / data-check output | G17: 开盘行情和数据链路检查。
A18: 2026-06-27 | B18: morning_review | C18: 10:30 | D18: overdue | F18: manual review / intraday check row | G18: 复核早盘触发、无效、止损纪律。
A19: 2026-06-27 | B19: midday_plan | C19: 12:10 | D19: pending | F19: midday pipeline record / daily log | G19: 上午结果和下午执行计划。
A20: 2026-06-27 | B20: afternoon_review | C20: 14:00 | D20: pending | F20: afternoon pipeline record / intraday check row | G20: 午后加减仓或继续观察复核。
A21: 2026-06-27 | B21: close_settlement | C21: 15:20 | D21: done | E21: 2026-06-27T10:50:29 | F21: /Users/hanlinye/Desktop/vibe 作品集/股票量化交易系统/trading-journal/pipeline-runs/2026-06-27/close.json | G21: pipeline close ok
A22: 2026-06-27 | B22: post_close_audit | C22: 16:30 | D22: pending | F22: pipeline_review / ops report | G22: 审计缺失阶段、失败链路和次日动作。
A23: 2026-06-29 | B23: preopen_plan | C23: 08:50 | D23: overdue | F23: daily log / preopen pipeline record | G23: 盘前计划、观察池、无效条件。
A24: 2026-06-29 | B24: open_snapshot | C24: 09:40 | D24: failed | E24: 2026-06-29T10:32:52 | F24: /Users/hanlinye/Desktop/vibe 作品集/股票量化交易系统/trading-journal/pipeline-runs/2026-06-29/open.json | G24: pipeline open failed
A25: 2026-06-29 | B25: morning_review | C25: 10:30 | D25: overdue | F25: manual review / intraday check row | G25: 复核早盘触发、无效、止损纪律。
A26: 2026-06-29 | B26: midday_plan | C26: 12:10 | D26: pending | F26: midday pipeline record / daily log | G26: 上午结果和下午执行计划。
A27: 2026-06-29 | B27: afternoon_review | C27: 14:00 | D27: pending | F27: afternoon pipeline record / intraday check row | G27: 午后加减仓或继续观察复核。
A28: 2026-06-29 | B28: close_settlement | C28: 15:20 | D28: pending | F28: DAY_SUMMARY / close pipeline record | G28: 结算权益、现金、持仓、盈亏和风险状态。
A29: 2026-06-29 | B29: post_close_audit | C29: 16:30 | D29: pending | F29: pipeline_review / ops report | G29: 审计缺失阶段、失败链路和次日动作。
A30: 2026-06-30 | B30: preopen_plan | C30: 08:50 | D30: overdue | F30: daily log / preopen pipeline record | G30: 盘前计划、观察池、无效条件。
A31: 2026-06-30 | B31: open_snapshot | C31: 09:40 | D31: done | E31: 2026-06-30T09:59:39 | F31: /Users/hanlinye/Desktop/vibe 作品集/股票量化交易系统/trading-journal/pipeline-runs/2026-06-30/open.json | G31: pipeline open ok
A32: 2026-06-30 | B32: morning_review | C32: 10:30 | D32: overdue | F32: manual review / intraday check row | G32: 复核早盘触发、无效、止损纪律。
A33: 2026-06-30 | B33: midday_plan | C33: 12:10 | D33: pending | F33: midday pipeline record / daily log | G33: 上午结果和下午执行计划。
A34: 2026-06-30 | B34: afternoon_review | C34: 14:00 | D34: pending | F34: afternoon pipeline record / intraday check row | G34: 午后加减仓或继续观察复核。
A35: 2026-06-30 | B35: close_settlement | C35: 15:20 | D35: pending | F35: DAY_SUMMARY / close pipeline record | G35: 结算权益、现金、持仓、盈亏和风险状态。
A36: 2026-06-30 | B36: post_close_audit | C36: 16:30 | D36: pending | F36: pipeline_review / ops report | G36: 审计缺失阶段、失败链路和次日动作。

Sheet 账户口径说明
A1: 项目 | B1: 日期 | C1: 数值 | D1: 说明
A2: 正式纸面账户期末权益 | D2: 来自交易总表的组合汇总行；这是账户净值口径。
A3: 正式纸面账户期末权益 | B3: 2026-06-23 | C3: 975434.47 | D3: 期初=975434.47；当日盈亏=0.0；现金=693805.47；市值=281629.0
A4: 正式纸面账户期末权益 | B4: 2026-06-24 | C4: 969598.01 | D4: 期初=975434.47；当日盈亏=-5836.46；现金=747105.91；市值=222492.1
A5: 正式纸面账户期末权益 | B5: 2026-06-25 | C5: 971318.91 | D5: 期初=969598.01；当日盈亏=1720.90；现金=747105.91；市值=224213.0
A6: 正式纸面账户期末权益 | B6: 2026-06-27 | C6: 968068.62 | D6: 期初=971318.91；当日盈亏=-3250.29；现金=841254.12；市值=126814.5
A7: 权益连续性检查 | B7: 2026-06-24 | C7: 通过 | D7: 2026-06-23期末=975434.47；2026-06-24期初=975434.47
A8: 权益连续性检查 | B8: 2026-06-25 | C8: 通过 | D8: 2026-06-24期末=969598.01；2026-06-25期初=969598.01
A9: 权益连续性检查 | B9: 2026-06-27 | C9: 通过 | D9: 2026-06-25期末=971318.91；2026-06-27期初=971318.91
A10: 回测结果，不计入账户净值 | B10: 2026-06-23 | C10: 期末权益1086989.62，总收益8.6990%，最大回撤10.8126%，Sharpe0.7550，交易314次，回测当前持仓600036/600941。；回测期末权益1086989.62 | D10: 回测是历史策略模拟收益，不是当天纸面账户收益；不得与组合汇总的总资产相加或比较为当日盈亏。
A11: 本次疑问解释 | D11: 6/23备注里的约8.7万收益来自回测期末权益1086989.62相对1000000初始资金，不是正式纸面账户当天收益；6/24总资产969598.01来自真实纸面持仓按当日价格结算。
